Workbook
Name Slicer_Category: #N/A
Name Slicer_City_cleaning: #N/A
Name Slicer_Clean_Payment_Method: #N/A
Name Slicer_Order_Status: #N/A
Name Slicer_Product: #N/A

Sheet Raw Data
A1: Order ID | B1: Order Date | C1: Customer ID | D1: Customer Name | E1: City | F1: Product | G1: Category | H1: Quantity | I1: Unit Price | J1: Discount % | K1: Payment Method | L1: Order Status | M1: Delivery Days
A2: ORD10001 | B2: 46125 | C2: CUST1150 | D2: Aditya | E2: Lucknow | F2: Power Bank | G2: Electronics | H2: 1 | I2: 37060 | J2: 0 | K2: UPI | L2: Delivered | M2: 6
A3: ORD10002 | B3: 46075 | C3: CUST1049 | D3: Pooja | E3: Chandigarh | F3: Hair Dryer | G3: Beauty | H3: 1 | I3: 1627 | J3: 5 | K3: Card | L3: Delivered | M3: 3
A4: ORD10003 | B4: 46081 | C4: CUST1051 | D4: Simran | E4: Noida | F4: Laptop Stand | G4: Electronics | H4: 1 | I4: 28095 | J4: 0 | K4: Card | L4: Delivered | M4: 3
A5: ORD10004 | B5: 46157 | C5: CUST1084 | D5: Rohan | E5: Delhi | F5: Laptop Stand | G5: Electronics | H5: 3 | I5: 44232 | J5: 15 | K5: UPI | L5: Delivered | M5: 4
A6: ORD10005 | B6: 46114 | C6: CUST1106 | D6: Aman | E6: Gurugram | F6: Power Bank | G6: Electronics | H6: 1 | I6: 13751 | J6: 20 | K6: UPI | L6: Delivered | M6: 4
A7: ORD10006 | B7: 46026 | C7: CUST1040 | D7: Aarav | E7: Delhi | F7: Green Tea | G7: Grocery | H7: 3 | I7: 700 | J7: 20 | K7: Card | L7: Cancelled | M7: 0
A8: ORD10007 | B8: 46104 | C8: CUST1089 | D8: Pooja | E8: Gurugram | F8: Table Lamp | G8: Home | H8: 1 | I8: 2271 | J8: 5 | K8: UPI | L8: Delivered | M8: 1
A9: ORD10008 | B9: 46093 | C9: CUST1135 | D9: Isha | E9: Gurugram | F9: Hoodie | G9: Fashion | H9: 2 | I9: 2300 | J9: 15 | K9: COD | L9: Delivered | M9: 3
A10: ORD10009 | B10: 46094 | C10: CUST1175 | D10: Isha | E10: Gurugram | F10: Power Bank | G10: Electronics | H10: 1 | I10: 4786 | J10: 5 | K10: Card | L10: Delivered | M10: 3
A11: ORD10010 | B11: 46153 | C11: CUST1096 | D11: Nikhil | E11: Lucknow | F11: Storage Box | G11: Home | H11: 2 | I11: 884 | J11: 0 | K11: Card | L11: Delivered | M11: 3
A12: ORD10011 | B12: 46154 | C12: CUST1086 | D12: Aman | E12: Jaipur | F12: Power Bank | G12: Electronics | H12: 2 | I12: 26302 | J12: 5 | K12: UPI | L12: Delivered | M12: 5
A13: ORD10012 | B13: 46050 | C13: CUST1075 | D13: Isha | E13: Jaipur | F13: Face Wash | G13: Beauty | H13: 2 | I13: 1270 | J13: 15 | K13: UPI | L13: Cancelled | M13: 0
... A227: ORD10226 | B227: 46127 | C227: CUST1069 | D227: Pooja | E227: Noida | F227: T-Shirt | G227: Fashion | H227: 2 | I227: 3400 | J227: 0 | K227: Card | L227: Returned | M227: 5
A228: ORD10227 | B228: 46070 | C228: CUST1065 | D228: Neha | E228: Lucknow | F228: Table Lamp | G228: Home | H228: 1 | I228: 1760 | K228: Card | L228: Delivered | M228: 5
A229: ORD10228 | B229: 46030 | C229: CUST1093 | D229: Sneha | E229: Gurugram | F229: Jeans | G229: Fashion | H229: 1 | I229: 2600 | J229: 15 | K229: Card | L229: Cancelled | M229: 0
A230: ORD10229 | B230: 46172 | C230: CUST1086 | D230: Aman | E230: Ghaziabad | F230: Water Bottle | G230: Home | H230: 2 | I230: 2052 | J230: 5 | K230: Card | L230: Delivered | M230: 3
A231: ORD10230 | B231: 46184 | C231: CUST1124 | D231: Rohan | E231: Gurugram | F231: Coffee | G231: Grocery | H231: 1 | I231: 1000 | J231: 10 | K231: UPI | L231: Delivered | M231: 1
A232: ORD10231 | B232: 46128 | C232: CUST1046 | D232: Aman | E232: Chandigarh | F232: Running Shoes | G232: Fashion | H232: 1 | I232: 700 | J232: 10 | K232: UPI | L232: Delivered | M232: 4
A233: ORD10232 | B233: 46135 | C233: CUST1107 | D233: Kavya | E233: Delhi | F233: Laptop Stand | G233: Electronics | H233: 1 | I233: 1200 | J233: 15 | K233: Card | L233: Delivered | M233: 4
A234: ORD10233 | B234: 46076 | C234: CUST1011 | D234: Simran | E234: Chandigarh | F234: T-Shirt | G234: Fashion | H234: 1 | I234: 2100 | J234: 0 | K234: UPI | L234: Delivered | M234: 4
A235: ORD10234 | B235: 46169 | C235: CUST1109 | D235: Pooja | E235: Gurugram | F235: Protein Bars | G235: Grocery | H235: 1 | I235: 150 | J235: 15 | K235: COD | L235: Delivered | M235: 3
A236: ORD10235 | B236: 46034 | C236: CUST1177 | D236: Riya | E236: Faridabad | F236: Backpack | G236: Fashion | H236: 3 | I236: 1100 | J236: 15 | K236: COD | L236: Delivered | M236: 6
A237: ORD10236 | B237: 46197 | C237: CUST1168 | D237: Arjun | E237: Jaipur | F237: Jeans | G237: Fashion | H237: 2 | I237: 3400 | J237: 10 | K237: UPI | L237: Delivered | M237: 5
A238: ORD10237 | B238: 46106 | C238: CUST1142 | D238: Rahul | E238: Jaipur | F238: Hoodie | G238: Fashion | H238: 2 | I238: 1900 | J238: 5 | K238: Card | L238: Delivered | M238: 5
A239: ORD10238 | B239: 46073 | C239: CUST1144 | D239: Rohan | E239: Jaipur | F239: Water Bottle | G239: Home | H239: 2 | I239: 446 | J239: 0 | K239: COD | L239: Delivered | M239: 5
A240: ORD10239 | B240: 46116 | C240: CUST1062 | D240: Rahul | E240: Delhi | F240: Laptop Stand | G240: Electronics | H240: 1 | I240: 4786 | J240: 0 | K240: UPI | L240: Cancelled | M240: 0
... A312: ORD10311 | B312: 46044 | C312: CUST1083 | D312: Priya | E312: Ghaziabad | F312: T-Shirt | G312: Fashion | H312: 1 | I312: 3200 | J312: 5 | K312: Net Banking | L312: Delivered | M312: 5
A313: ORD10312 | B313: 46151 | C313: CUST1127 | E313: Noida | F313: Hair Dryer | G313: Beauty | H313: 4 | I313: 505 | J313: 0 | K313: UPI | L313: Delivered | M313: 3
A314: ORD10313 | B314: 46175 | C314: CUST1121 | D314: Ananya | E314: Gurugram | F314: T-Shirt | G314: Fashion | H314: 2 | I314: 3100 | J314: 0 | K314: Card | L314: Delivered | M314: 4
A315: ORD10314 | B315: 46063 | C315: CUST1176 | D315: Nikhil | E315: Noida | F315: Face Wash | G315: Beauty | H315: 2 | I315: 1270 | J315: 15 | K315: UPI | L315: Delivered | M315: 2
A316: ORD10315 | B316: 46056 | C316: CUST1138 | D316: Varun | E316: Delhi | F316: Hoodie | G316: Fashion | H316: 1 | I316: 3400 | J316: 10 | K316: UPI | L316: Cancelled | M316: 0
A317: ORD10316 | B317: 46104 | C317: CUST1120 | D317: Aarav | E317: Lucknow | F317: Moisturizer | G317: Beauty | H317: 1 | I317: 1780 | J317: 5 | K317: Card | L317: Delivered | M317: 1
A318: ORD10317 | B318: 46113 | C318: CUST1137 | D318: Riya | E318: Gurugram | F318: Bluetooth Speaker | G318: Electronics | H318: 3 | I318: 29888 | J318: 10 | K318: Card | L318: Delivered | M318: 5
A319: ORD10318 | B319: 46104 | C319: CUST1107 | D319: Kavya | E319: Lucknow | F319: T-Shirt | G319: Fashion | H319: 1 | I319: 3000 | J319: 15 | K319: Card | L319: Delivered | M319: 4
A320: ORD10319 | B320: 46059 | C320: CUST1129 | D320: Pooja | E320: Lucknow | F320: Hoodie | G320: Fashion | H320: 1 | I320: 3000 | J320: 5 | K320: Card | L320: Delivered | M320: 6
A321: ORD10320 | B321: 46077 | C321: CUST1092 | D321: Vivek | E321: Faridabad | F321: Wireless Earbuds | G321: Electronics | H321: 3 | I321: 1200 | J321: 0 | K321: Card | L321: Delivered | M321: 3
A322: ORD10321 | B322: 46043 | C322: CUST1021 | D322: Ananya | E322: Faridabad | F322: Shampoo | G322: Beauty | H322: 1 | I322: 1168 | J322: 5 | K322: UPI | L322: Delivered | M322: 6
A323: ORD10322 | B323: 46083 | C323: CUST1177 | D323: Riya | E323: Noida | F323: Face Wash | G323: Beauty | H323: 1 | I323: 862 | J323: 20 | K323: Net Banking | L323: Delivered | M323: 4
A324: ORD10323 | B324: 46128 | C324: CUST1087 | D324: Kavya | E324: Noida | F324: Wireless Earbuds | G324: Electronics | H324: 3 | I324: 37060 | J324: 0 | K324: COD | L324: Delivered | M324: 5
...

Sheet pivot 
A1: Which category generates the most sales?
A3: Row Labels | B3: Sum of Sales Amount
A4: Beauty | B4: 102602
A5: Electronics | B5: 5158708
A6: Fashion | B6: 435300
A7: Grocery | B7: 98100
A8: Home | B8: 219234
A9: (blank)
A12: Which category has the most orders?
A15: Row Labels | B15: Count of Order ID
A16: Beauty | B16: 72
A17: Electronics | B17: 129
A18: Fashion | B18: 131
A19: Grocery | B19: 65
A20: Home | B20: 103
A21: (blank)
A22: Grand Total | B22: 500
A24: “Which payment method is used most frequently by customers?”
A27: Row Labels | B27: Count of Order ID
A28: Card | B28: 135
A29: COD | B29: 129
A30: Net Banking | B30: 36
A31: UPI | B31: 200
A32: (blank)
A33: Grand Total | B33: 500
G34: “What is the total sales by payment method?”
A35: “What is the current order status distribution?”
G36: Row Labels | H36: Sum of Sales Amount
A37: Row Labels | B37: Count of Order ID | G37: Card | H37: 1419039
A38: Cancelled | B38: 33 | G38: COD | H38: 1300229
A39: Delivered | B39: 446 | G39: Net Banking | H39: 472890
A40: Returned | B40: 21 | G40: UPI | H40: 2821786
A41: (blank) | G41: (blank)
A44: “What is the average delivery time for each category?” | D44: Which cities have the highest number of orders?
A47: Row Labels | B47: Average of Delivery Days | D47: Row Labels | E47: Count of Order ID
A48: Beauty | B48: 2.25 | D48: Chandigarh | E48: 44
A49: Electronics | B49: 3.4418605 | D49: Delhi | E49: 99
A50: Fashion | B50: 4.3816794 | D50: Faridabad | E50: 43
A51: Grocery | B51: 1.7692308 | D51: Ghaziabad | E51: 54
A52: Home | B52: 3.1650485 | D52: Gurugram | E52: 76
...

Sheet Dashboard
L4: E-Commerce Business Performance & Insights
R65: KEY BUSINESS INSIGHTS
R67: Q1. Which category generates the most sales?
R68: • Electronics generated the highest sales with ₹51,58,708.
R70: Q2. Which month generated the highest sales?
R71: • May recorded the highest monthly sales with ₹12,76,404.
R73: Q3. Which payment method generated the highest sales?
R74: • UPI generated the highest sales with ₹28,21,786.
R76: Q4. Which product generated the highest sales?
R77: • Power Bank generated the highest sales with ₹14,84,263.
R79: Q5. Which product has the highest number of orders?
R80: • Power Bank had the highest number of orders with 36 orders.
R82: Q6. What percentage of orders were successfully delivered?
... R95: • The business received 500 orders.

Sheet Cleaned data
A1: Order ID | B1: Order Date | C1: clean order date | D1: Customer ID | E1: Customer Name | F1: Clean Customer Name | G1: City | H1: City-wise Analysis | I1: City cleaning | J1: Product | K1: sum if | L1: Product | M1: sum if | N1: Category | O1: Quantity | P1: Unit Price | Q1: Discount % | R1: Sales Amount | S1: Payment Method | T1: Clean Payment Method | V1: Order Status | W1: Delivery Days
A2: ORD10001 | B2: 46125 | C2: {=TEXT(B2:B501,"mmm")} -> Apr | D2: CUST1150 | E2: Aditya | F2: =TRIM(E2) -> Aditya | G2: Lucknow | H2: {=COUNTIF(G2:G403,G2:G403)} -> 49 | I2: =TRIM(G2) -> Lucknow | J2: Power Bank | K2: {=SUMIF(J2:J501,J2:J501,O2:O500)} -> 55 | L2: Backpack | M2: {=SUMIF(J2:J501,L2:L26,R2:R501)} -> 98600 | N2: Electronics | O2: 1 | P2: 37060 | Q2: 0 | R2: =O2*P2 -> 37060 | S2: UPI | T2: =TRIM(S2) -> UPI | U2: {=COUNTIF(T2:T501,S2:S501)} -> 200 | V2: Delivered | W2: 6
A3: ORD10002 | B3: 46075 | C3: Feb | D3: CUST1049 | E3: Pooja | F3: =TRIM(E3) -> Pooja | G3: Chandigarh | H3: 35 | I3: =TRIM(G3) -> Chandigarh | J3: Hair Dryer | K3: 20 | L3: Bedsheet Set | M3: 39173 | N3: Beauty | O3: 1 | P3: 1627 | Q3: 5 | R3: =O3*P3 -> 1627 | S3: Card | T3: =TRIM(S3) -> Card | U3: 135 | V3: Delivered | W3: 3
A4: ORD10003 | B4: 46081 | C4: Feb | D4: CUST1051 | E4: Simran | F4: =TRIM(E4) -> Simran | G4: Noida | H4: 64 | I4: =TRIM(G4) -> Noida | J4: Laptop Stand | K4: 36 | L4: Body Lotion | M4: 26645 | N4: Electronics | O4: 1 | P4: 28095 | Q4: 0 | R4: =O4*P4 -> 28095 | S4: Card | T4: =TRIM(S4) -> Card | U4: 135 | V4: Delivered | W4: 3
A5: ORD10004 | B5: 46157 | C5: May | D5: CUST1084 | E5: Rohan | F5: =TRIM(E5) -> Rohan | G5: Delhi | H5: 73 | I5: =TRIM(G5) -> Delhi | J5: Laptop Stand | K5: 36 | L5: Bluetooth Speaker | M5: 1245131 | N5: Electronics | O5: 3 | P5: 44232 | Q5: 15 | R5: =O5*P5 -> 132696 | S5: UPI | T5: =TRIM(S5) -> UPI | U5: 200 | V5: Delivered | W5: 4
A6: ORD10005 | B6: 46114 | C6: Apr | D6: CUST1106 | E6: Aman | F6: =TRIM(E6) -> Aman | G6: Gurugram | H6: 69 | I6: =TRIM(G6) -> Gurugram | J6: Power Bank | K6: 55 | L6: Coffee | M6: 10750 | N6: Electronics | O6: 1 | P6: 13751 | Q6: 20 | R6: =O6*P6 -> 13751 | S6: UPI | T6: =TRIM(S6) -> UPI | U6: 200 | V6: Delivered | W6: 4
A7: ORD10006 | B7: 46026 | C7: Jan | D7: CUST1040 | E7: Aarav | F7: =TRIM(E7) -> Aarav | G7: Delhi | H7: 73 | I7: =TRIM(G7) -> Delhi | J7: Green Tea | K7: 29 | L7: Cushion Set | M7: 37527 | N7: Grocery | O7: 3 | P7: 700 | Q7: 20 | R7: =O7*P7 -> 2100 | S7: Card | T7: =TRIM(S7) -> Card | U7: 135 | V7: Cancelled | W7: 0
A8: ORD10007 | B8: 46104 | C8: Mar | D8: CUST1089 | E8: Pooja | F8: =TRIM(E8) -> Pooja | G8: Gurugram | H8: 69 | I8: =TRIM(G8) -> Gurugram | J8: Table Lamp | K8: 29 | L8: Face Wash | M8: 24518 | N8: Home | O8: 1 | P8: 2271 | Q8: 5 | R8: =O8*P8 -> 2271 | S8: UPI | T8: =TRIM(S8) -> UPI | U8: 200 | V8: Delivered | W8: 1
A9: ORD10008 | B9: 46093 | C9: Mar | D9: CUST1135 | E9: Isha | F9: =TRIM(E9) -> Isha | G9: Gurugram | H9: 69 | I9: =TRIM(G9) -> Gurugram | J9: Hoodie | K9: 31 | L9: Dry Fruits | M9: 28000 | N9: Fashion | O9: 2 | P9: 2300 | Q9: 15 | R9: =O9*P9 -> 4600 | S9: COD | T9: =TRIM(S9) -> COD | U9: 129 | V9: Delivered | W9: 3
A10: ORD10009 | B10: 46094 | C10: Mar | D10: CUST1175 | E10: Isha | F10: =TRIM(E10) -> Isha | G10: Gurugram | H10: 69 | I10: =TRIM(G10) -> Gurugram | J10: Power Bank | K10: 55 | L10: Hair Dryer | M10: 20657 | N10: Electronics | O10: 1 | P10: 4786 | Q10: 5 | R10: =O10*P10 -> 4786 | S10: Card | T10: =TRIM(S10) -> Card | U10: 135 | V10: Delivered | W10: 3
A11: ORD10010 | B11: 46153 | C11: May | D11: CUST1096 | E11: Nikhil | F11: =TRIM(E11) -> Nikhil | G11: Lucknow | H11: 49 | I11: =TRIM(G11) -> Lucknow | J11: Storage Box | K11: 33 | L11: Green Tea | M11: 24550 | N11: Home | O11: 2 | P11: 884 | Q11: 0 | R11: =O11*P11 -> 1768 | S11: Card | T11: =TRIM(S11) -> Card | U11: 135 | V11: Delivered | W11: 3
A12: ORD10011 | B12: 46154 | C12: May | D12: CUST1086 | E12: Aman | F12: =TRIM(E12) -> Aman | G12: Jaipur | H12: 36 | I12: =TRIM(G12) -> Jaipur | J12: Power Bank | K12: 55 | L12: Hoodie | M12: 69600 | N12: Electronics | O12: 2 | P12: 26302 | Q12: 5 | R12: =O12*P12 -> 52604 | S12: UPI | T12: =TRIM(S12) -> UPI | U12: 200 | V12: Delivered | W12: 5
A13: ORD10012 | B13: 46050 | C13: Jan | D13: CUST1075 | E13: Isha | F13: =TRIM(E13) -> Isha | G13: Jaipur | H13: 36 | I13: =TRIM(G13) -> Jaipur | J13: Face Wash | K13: 23 | L13: Jeans | M13: 119500 | N13: Beauty | O13: 2 | P13: 1270 | Q13: 15 | R13: =O13*P13 -> 2540 | S13: UPI | T13: =TRIM(S13) -> UPI | U13: 200 | V13: Cancelled | W13: 0
A14: ORD10013 | B14: 46150 | C14: May | D14: CUST1137 | E14: Riya | F14: =TRIM(E14) -> Riya | G14: Lucknow | H14: 49 | I14: =TRIM(G14) -> Lucknow | J14: Coffee | K14: 14 | L14: Laptop Stand | M14: 1176376 | N14: Grocery | O14: 1 | P14: 150 | Q14: 5 | R14: =O14*P14 -> 150 | S14: COD | T14: =TRIM(S14) -> COD | U14: 129 | V14: Delivered | W14: 2
... A26: ORD10025 | B26: 46057 | C26: Feb | D26: CUST1037 | E26: Riya | F26: =TRIM(E26) -> Riya | G26: Lucknow | H26: 49 | I26: =TRIM(G26) -> Lucknow | J26: Laptop Stand | K26: 36 | L26: Wireless Earbuds | M26: 832713 | N26: Electronics | O26: 1 | P26: 49611 | Q26: 5 | R26: =O26*P26 -> 49611 | S26: COD | T26: =TRIM(S26) -> COD | U26: 129 | V26: Delivered | W26: 1
A27: ORD10026 | B27: 46046 | C27: Jan | D27: CUST1025 | E27: Neha | F27: =TRIM(E27) -> Neha | G27: Noida | H27: 64 | I27: =TRIM(G27) -> Noida | J27: Storage Box | K27: 33 | N27: Home | O27: 2 | P27: 2271 | Q27: 5 | R27: =O27*P27 -> 4542 | S27: UPI | T27: =TRIM(S27) -> UPI | U27: 200 | V27: Delivered | W27: 2
A28: ORD10027 | B28: 46076 | C28: Feb | D28: CUST1017 | E28: Riya | F28: =TRIM(E28) -> Riya | G28: Faridabad | H28: 35 | I28: =TRIM(G28) -> Faridabad | J28: Bedsheet Set | K28: 33 | M28: =SUM(_xlfn.ANCHORARRAY(M2)) -> 6013944 | N28: Home | O28: 4 | P28: 1322 | Q28: 0 | R28: =O28*P28 -> 5288 | S28: Card | T28: =TRIM(S28) -> Card | U28: 135 | V28: Delivered | W28: 3
A29: ORD10028 | B29: 46126 | C29: Apr | D29: CUST1135 | E29: Isha | F29: =TRIM(E29) -> Isha | G29: Faridabad | H29: 35 | I29: =TRIM(G29) -> Faridabad | J29: Body Lotion | K29: 26 | N29: Beauty | O29: 2 | P29: 709 | Q29: 15 | R29: =O29*P29 -> 1418 | S29: COD | T29: =TRIM(S29) -> COD | U29: 129 | V29: Cancelled | W29: 0
A30: ORD10029 | B30: 46079 | C30: Feb | D30: CUST1063 | E30: Priya | F30: =TRIM(E30) -> Priya | G30: Ghaziabad | H30: 40 | I30: =TRIM(G30) -> Ghaziabad | J30: Laptop Stand | K30: 36 | N30: Electronics | O30: 1 | P30: 33474 | Q30: 5 | R30: =O30*P30 -> 33474 | S30: UPI | T30: =TRIM(S30) -> UPI | U30: 200 | V30: Delivered | W30: 3
A31: ORD10030 | B31: 46147 | C31: May | D31: CUST1008 | E31: Arjun | F31: =TRIM(E31) -> Arjun | G31: Lucknow | H31: 49 | I31: =TRIM(G31) -> Lucknow | J31: Coffee | K31: 14 | N31: Grocery | O31: 1 | P31: 1100 | Q31: 5 | R31: =O31*P31 -> 1100 | S31: Card | T31: =TRIM(S31) -> Card | U31: 135 | V31: Delivered | W31: 1
A32: ORD10031 | B32: 46075 | C32: Feb | D32: CUST1145 | E32: Neha | F32: =TRIM(E32) -> Neha | G32: Noida | H32: 64 | I32: =TRIM(G32) -> Noida | J32: Oats | K32: 10 | N32: Grocery | O32: 1 | P32: 400 | Q32: 10 | R32: =O32*P32 -> 400 | S32: Card | T32: =TRIM(S32) -> Card | U32: 135 | V32: Delivered | W32: 1
A33: ORD10032 | B33: 46142 | C33: Apr | D33: CUST1129 | E33: Pooja | F33: =TRIM(E33) -> Pooja | G33: Noida | H33: 64 | I33: =TRIM(G33) -> Noida | J33: Backpack | K33: 44 | N33: Fashion | O33: 1 | P33: 900 | Q33: 0 | R33: =O33*P33 -> 900 | S33: Card | T33: =TRIM(S33) -> Card | U33: 135 | V33: Delivered | W33: 5
A34: ORD10033 | B34: 46080 | C34: Feb | D34: CUST1076 | E34: Nikhil | F34: =TRIM(E34) -> Nikhil | G34: Jaipur | H34: 36 | I34: =TRIM(G34) -> Jaipur | J34: Running Shoes | K34: 41 | N34: Fashion | O34: 3 | P34: 1200 | Q34: 10 | R34: =O34*P34 -> 3600 | S34: Card | T34: =TRIM(S34) -> Card | U34: 135 | V34: Delivered | W34: 7
A35: ORD10034 | B35: 46176 | C35: Jun | D35: CUST1144 | E35: Rohan | F35: =TRIM(E35) -> Rohan | G35: Noida | H35: 64 | I35: =TRIM(G35) -> Noida | J35: Face Wash | K35: 23 | N35: Beauty | O35: 1 | P35: 1678 | Q35: 0 | R35: =O35*P35 -> 1678 | S35: UPI | T35: =TRIM(S35) -> UPI | U35: 200 | V35: Delivered | W35: 2
A36: ORD10035 | B36: 46198 | C36: Jun | D36: CUST1004 | E36: Rohan | F36: =TRIM(E36) -> Rohan | G36: Lucknow | H36: 49 | I36: =TRIM(G36) -> Lucknow | J36: T-Shirt | K36: 27 | N36: Fashion | O36: 1 | P36: 2700 | Q36: 20 | R36: =O36*P36 -> 2700 | S36: COD | T36: =TRIM(S36) -> COD | U36: 129 | V36: Delivered | W36: 9
A37: ORD10036 | B37: 46038 | C37: Jan | D37: CUST1124 | E37: Rohan | F37: =TRIM(E37) -> Rohan | G37: Delhi | H37: 73 | I37: =TRIM(G37) -> Delhi | J37: Table Lamp | K37: 29 | N37: Home | O37: 1 | P37: 2271 | Q37: 20 | R37: =O37*P37 -> 2271 | S37: Card | T37: =TRIM(S37) -> Card | U37: 135 | V37: Delivered | W37: 4
A38: ORD10037 | B38: 46055 | C38: Feb | D38: CUST1008 | E38: Arjun | F38: =TRIM(E38) -> Arjun | G38: Gurugram | H38: 69 | I38: =TRIM(G38) -> Gurugram | J38: Cushion Set | K38: 28 | N38: Home | O38: 1 | P38: 1103 | Q38: 25 | R38: =O38*P38 -> 1103 | S38: COD | T38: =TRIM(S38) -> COD | U38: 129 | V38: Delivered | W38: 3
A39: ORD10038 | B39: 46115 | C39: Apr | D39: CUST1157 | E39: Riya | F39: =TRIM(E39) -> Riya | G39: Lucknow | H39: 49 | I39: =TRIM(G39) -> Lucknow | J39: Bluetooth Speaker | K39: 41 | N39: Electronics | O39: 1 | P39: 33474 | Q39: 0 | R39: =O39*P39 -> 33474 | S39: Card | T39: =TRIM(S39) -> Card | U39: 135 | V39: Delivered | W39: 4
A40: ORD10039 | B40: 46142 | C40: Apr | D40: CUST1096 | E40: Nikhil | F40: =TRIM(E40) -> Nikhil | G40: Faridabad | H40: 35 | I40: =TRIM(G40) -> Faridabad | J40: Face Wash | K40: 23 | N40: Beauty | O40: 1 | P40: 403 | Q40: 15 | R40: =O40*P40 -> 403 | S40: COD | T40: =TRIM(S40) -> COD | U40: 129 | V40: Returned | W40: 1
... A227: ORD10226 | B227: 46127 | C227: Apr | D227: CUST1069 | E227: Pooja | F227: =TRIM(E227) -> Pooja | G227: Noida | H227: 64 | I227: =TRIM(G227) -> Noida | J227: T-Shirt | K227: 27 | N227: Fashion | O227: 2 | P227: 3400 | Q227: 0 | R227: =O227*P227 -> 6800 | S227: Card | T227: =TRIM(S227) -> Card | U227: 135 | V227: Returned | W227: 5
A228: ORD10227 | B228: 46070 | C228: Feb | D228: CUST1065 | E228: Neha | F228: =TRIM(E228) -> Neha | G228: Lucknow | H228: 49 | I228: =TRIM(G228) -> Lucknow | J228: Table Lamp | K228: 29 | N228: Home | O228: 1 | P228: 1760 | R228: =O228*P228 -> 1760 | S228: Card | T228: =TRIM(S228) -> Card | U228: 135 | V228: Delivered | W228: 5
A229: ORD10228 | B229: 46030 | C229: Jan | D229: CUST1093 | E229: Sneha | F229: =TRIM(E229) -> Sneha | G229: Gurugram | H229: 69 | I229: =TRIM(G229) -> Gurugram | J229: Jeans | K229: 54 | N229: Fashion | O229: 1 | P229: 2600 | Q229: 15 | R229: =O229*P229 -> 2600 | S229: Card | T229: =TRIM(S229) -> Card | U229: 135 | V229: Cancelled | W229: 0
A230: ORD10229 | B230: 46172 | C230: May | D230: CUST1086 | E230: Aman | F230: =TRIM(E230) -> Aman | G230: Ghaziabad | H230: 40 | I230: =TRIM(G230) -> Ghaziabad | J230: Water Bottle | K230: 34 | N230: Home | O230: 2 | P230: 2052 | Q230: 5 | R230: =O230*P230 -> 4104 | S230: Card | T230: =TRIM(S230) -> Card | U230: 135 | V230: Delivered | W230: 3
A231: ORD10230 | B231: 46184 | C231: Jun | D231: CUST1124 | E231: Rohan | F231: =TRIM(E231) -> Rohan | G231: Gurugram | H231: 69 | I231: =TRIM(G231) -> Gurugram | J231: Coffee | K231: 14 | N231: Grocery | O231: 1 | P231: 1000 | Q231: 10 | R231: =O231*P231 -> 1000 | S231: UPI | T231: =TRIM(S231) -> UPI | U231: 200 | V231: Delivered | W231: 1
A232: ORD10231 | B232: 46128 | C232: Apr | D232: CUST1046 | E232: Aman | F232: =TRIM(E232) -> Aman | G232: Chandigarh | H232: 35 | I232: =TRIM(G232) -> Chandigarh | J232: Running Shoes | K232: 41 | N232: Fashion | O232: 1 | P232: 700 | Q232: 10 | R232: =O232*P232 -> 700 | S232: UPI | T232: =TRIM(S232) -> UPI | U232: 200 | V232: Delivered | W232: 4
A233: ORD10232 | B233: 46135 | C233: Apr | D233: CUST1107 | E233: Kavya | F233: =TRIM(E233) -> Kavya | G233: Delhi | H233: 73 | I233: =TRIM(G233) -> Delhi | J233: Laptop Stand | K233: 36 | N233: Electronics | O233: 1 | P233: 1200 | Q233: 15 | R233: =O233*P233 -> 1200 | S233: Card | T233: =TRIM(S233) -> Card | U233: 135 | V233: Delivered | W233: 4
A234: ORD10233 | B234: 46076 | C234: Feb | D234: CUST1011 | E234: Simran | F234: =TRIM(E234) -> Simran | G234: Chandigarh | H234: 35 | I234: =TRIM(G234) -> Chandigarh | J234: T-Shirt | K234: 27 | N234: Fashion | O234: 1 | P234: 2100 | Q234: 0 | R234: =O234*P234 -> 2100 | S234: UPI | T234: =TRIM(S234) -> UPI | U234: 200 | V234: Delivered | W234: 4
A235: ORD10234 | B235: 46169 | C235: May | D235: CUST1109 | E235: Pooja | F235: =TRIM(E235) -> Pooja | G235: Gurugram | H235: 69 | I235: =TRIM(G235) -> Gurugram | J235: Protein Bars | K235: 28 | N235: Grocery | O235: 1 | P235: 150 | Q235: 15 | R235: =O235*P235 -> 150 | S235: COD | T235: =TRIM(S235) -> COD | U235: 129 | V235: Delivered | W235: 3
A236: ORD10235 | B236: 46034 | C236: Jan | D236: CUST1177 | E236: Riya | F236: =TRIM(E236) -> Riya | G236: Faridabad | H236: 35 | I236: =TRIM(G236) -> Faridabad | J236: Backpack | K236: 44 | N236: Fashion | O236: 3 | P236: 1100 | Q236: 15 | R236: =O236*P236 -> 3300 | S236: COD | T236: =TRIM(S236) -> COD | U236: 129 | V236: Delivered | W236: 6
A237: ORD10236 | B237: 46197 | C237: Jun | D237: CUST1168 | E237: Arjun | F237: =TRIM(E237) -> Arjun | G237: Jaipur | H237: 36 | I237: =TRIM(G237) -> Jaipur | J237: Jeans | K237: 54 | N237: Fashion | O237: 2 | P237: 3400 | Q237: 10 | R237: =O237*P237 -> 6800 | S237: UPI | T237: =TRIM(S237) -> UPI | U237: 200 | V237: Delivered | W237: 5
...

Sheet Analysis sheet
A1: Total Orders | C1: : Cancelled Orders | E1: Returned Orders | G1: Delivered Orders | I1: : Total Quantity Sold | L1: Total Sales | N1: Average Delivery Days | P1: Average Order Value
A2: =COUNTA('Cleaned data'!A2:A501) -> 500 | C2: =COUNTIF('Cleaned data'!V2:V501,"Cancelled") -> 33 | E2: =COUNTIF('Cleaned data'!V2:V501,"Returned") -> 21 | G2: =COUNTIF('Cleaned data'!V2:V501,"Delivered") -> 446 | I2: =SUM('Cleaned data'!O2:O501) -> 750 | L2: =SUM('Cleaned data'!R2:R501) -> 6013944 | N2: =AVERAGE('Cleaned data'!W2:W501) -> 3.242 | P2: =AVERAGE('Cleaned data'!R2:R501) -> 12027.888
C5: category count
A6: Fashion → 131 | C6: =COUNTIF('Cleaned data'!N2:N501,"Fashion") -> 131 | I6: Category | J6: Orders | K6: Total Sales | R6: City | S6: Orders
A7: Electronics → 129 | C7: =COUNTIF('Cleaned data'!N2:N501,"Electronics") -> 129 | I7: Electronics | J7: 129 | K7: 5158708 | N7: Product | O7: Total Quantity | R7: Delhi | S7: 73
A8: Home → 103 | C8: =COUNTIF('Cleaned data'!N2:N501,"Home") -> 103 | I8: Fashion | J8: 131 | K8: 435300 | N8: Backpack | O8: 44 | P8: =SUM(O8:O32) -> 750 | R8: Noida | S8: 64
A9: Beauty → 72 | C9: =COUNTIF('Cleaned data'!N2:N501,"Beauty") -> 72 | I9: Home | J9: 103 | K9: 219234 | N9: Bedsheet Set | O9: 33 | R9: Gurugram | S9: 69 | AC9: Category | AD9: Cancelled Orders | AE9: rate
A10: Grocery → 65 | C10: =COUNTIF('Cleaned data'!N2:N501,"Grocery") -> 65 | F10: =SUMIF('Cleaned data'!O6:O505,"Fashion",'Cleaned data'!S6:S505) -> 0 | I10: Beauty | J10: 72 | K10: 102602 | N10: Body Lotion | O10: 26 | R10: Ghaziabad | S10: 40 | X10: Order Status | Y10: Orders | Z10: Rate % | AC10: Electronics | AD10: 6 | AE10: =AD10/AF10*100 -> 4.6511628 | AF10: 129
I11: Grocery | J11: 65 | K11: 98100 | N11: Bluetooth Speaker | O11: 41 | R11: Faridabad | S11: 35 | X11: Delivered | Y11: 446 | Z11: =Y11/Y14*100 -> 89.2 | AC11: Fashion | AD11: 4 | AE11: =AD11/AF11*100 -> 3.0534351 | AF11: 131
N12: Coffee | O12: 14 | R12: Lucknow | S12: 49 | X12: Cancelled | Y12: 33 | Z12: =Y12/Y14*100 -> 6.6 | AC12: Home | AD12: 10 | AE12: =AD12/AF12*100 -> 9.7087379 | AF12: 103
N13: Cushion Set | O13: 28 | R13: Jaipur | S13: 36 | X13: Returned | Y13: 21 | Z13: =Y13/Y14*100 -> 4.2 | AC13: Beauty | AD13: 9 | AE13: =AD13/AF13*100 -> 12.5 | AF13: 72
N14: Face Wash | O14: 23 | R14: Chandigarh | S14: 35 | X14: Total | Y14: 500 | AC14: Grocery | AD14: 4 | AE14: =AD14/AF14*100 -> 6.1538462 | AF14: 65
I15: =SUMIF('Cleaned data'!R11:R510,"Home",'Cleaned data'!W11:W510) -> 0 | N15: Dry Fruits | O15: 30 | R15: Total | S15: 401 | AC15: Total | AD15: 33 | AE15: =AD15/AF15*100 -> #DIV/0!
E16: Payment Method | F16: Orders | N16: Hair Dryer | O16: 20
E17: UPI | F17: 200 | G17: =SUM(F17:F20) -> 500 | N17: Green Tea | O17: 29
E18: Card | F18: 135 | N18: Hoodie | O18: 31 | AC18: Month | AD18: Total Sales
E19: COD | F19: 129 | K19: =AVERAGEIF(H19:H518,J19,V19:V518) -> #DIV/0! | N19: Jeans | O19: 54 | U19: Category | V19: Cancelled Orders | AC19: Jan | AD19: 715402
E20: Net Banking | F20: 36 | K20: =AVERAGEIF(H20:H519,J20,V20:V519) -> #DIV/0! | N20: Laptop Stand | O20: 36 | U20: Electronics | V20: =COUNTIFS('Cleaned data'!N2:N501,"") -> 0 | AC20: Feb | AD20: 965237
K21: =AVERAGEIF(H21:H520,J21,V21:V520) -> #DIV/0! | N21: Moisturizer | O21: 18 | U21: Fashion | AC21: Mar | AD21: 1107093
K22: =AVERAGEIF(H22:H521,J22,V22:V521) -> #DIV/0! | N22: Oats | O22: 10 | U22: Home | AC22: Apr | AD22: 910743
K23: =AVERAGEIF(H23:H522,J23,V23:V522) -> #DIV/0! | N23: Power Bank | O23: 55 | U23: Beauty | AC23: May | AD23: 1276404
I24: =AVERAGEIF(F24:F523,H24,T24:T523) -> #DIV/0! | N24: Protein Bars | O24: 28 | U24: Grocery | AC24: Jun | AD24: 1039065
I25: =AVERAGEIF(F25:F524,H25,T25:T524) -> #DIV/0! | N25: Running Shoes | O25: 41
I26: =AVERAGEIF(F26:F525,H26,T26:T525) -> #DIV/0! | N26: Shampoo | O26: 17
I27: =AVERAGEIF(F27:F526,H27,T27:T526) -> #DIV/0! | N27: Smart Watch | O27: 14
I28: =AVERAGEIF(F28:F527,H28,T28:T527) -> #DIV/0! | N28: Storage Box | O28: 33
N29: Table Lamp | O29: 29
N30: T-Shirt | O30: 27
N31: Water Bottle | O31: 34
N32: Wireless Earbuds | O32: 35
